Workbook

Sheet Sheet1
A1: Name | B1: Age | C1: Gender | D1: Mobile Number | E1: Order ID | F1: TEST | G1: STATUS | H1: Date | I1: Customer id | J1: Customer id | K1: Reports links
A2: Sarita Madhukar Mohit | B2: 48 | C2: Female | D2: 9960762191 | E2: VL6C0036 | F2: HBA1C / Total Cholesterol | G2: REPORTED | H2: 46216 | I2: =VLOOKUP(E2,Sheet2!A:C,3,0) -> AF28314700086087049 | J2: AF28314700086087049 | K2: https://www.thyrocare.com/DownloadReports/?token=12bdab28-c02a-4f6c-a02b-725053ce1e9e
A3: Prafulla Talekar | B3: 39 | C3: Male | D3: 7709112809 | E3: VL1AF35E | F3: HBA1C / Total Cholesterol | G3: REPORTED | H3: 46216 | I3: =VLOOKUP(E3,Sheet2!A:C,3,0) -> PE00213700086079892 | J3: PE00213700086079892 | K3: https://www.thyrocare.com/DownloadReports/?token=93cd5513-f01f-4183-bb30-e40ded094749
A4: Sagar Kothari | B4: 45 | C4: Male | D4: 9820744923 | E4: VL728397 | F4: HBA1C / Total Cholesterol | G4: REPORTED | H4: 46216 | I4: =VLOOKUP(E4,Sheet2!A:C,3,0) -> PE00213700086078475 | J4: PE00213700086078475 | K4: https://www.thyrocare.com/DownloadReports/?token=0f469a37-8584-4ec7-bba3-99cffe6810b1
A5: Chetan chandrakant shintre | B5: 50 | C5: Male | D5: 9223288180 | E5: VL99447E | F5: HBA1C / Total Cholesterol | G5: REPORTED | H5: 46216 | I5: =VLOOKUP(E5,Sheet2!A:C,3,0) -> PE00213700086078627 | J5: PE00213700086078627 | K5: https://www.thyrocare.com/DownloadReports/?token=cc7f39bc-9260-4c04-9bfa-b4e606e77844
A6: Haresh Gurshani | B6: 63 | C6: Male | D6: 9820626779 | E6: VLEBFCE1 | F6: HBA1C / Total Cholesterol | G6: REPORTED | H6: 46216 | I6: =VLOOKUP(E6,Sheet2!A:C,3,0) -> PE00213700086078872 | J6: PE00213700086078872 | K6: https://www.thyrocare.com/DownloadReports/?token=041d2a6d-ab4a-4ecc-88f0-8ec0c042c1b8
A7: Devendra Shirodkar | B7: 53 | C7: Male | D7: 9967645698 | E7: VL7A98D8 | F7: HBA1C / Total Cholesterol | G7: REPORTED | H7: 46216 | I7: =VLOOKUP(E7,Sheet2!A:C,3,0) -> PE00213700086079018 | J7: PE00213700086079018 | K7: https://www.thyrocare.com/DownloadReports/?token=6f5f7d8a-d550-4848-b859-960467d671e5
A8: Dnyaneshwar Patil | B8: 42 | C8: Male | D8: 9423904021 | E8: VL4F389B | F8: HBA1C / Total Cholesterol | G8: REPORTED | H8: 46216 | I8: =VLOOKUP(E8,Sheet2!A:C,3,0) -> PE00213700086079091 | J8: PE00213700086079091 | K8: https://www.thyrocare.com/DownloadReports/?token=66f80468-ba82-41ba-ab02-5442ccbdae96
A9: Sandeep Jagdale | B9: 46 | C9: Male | D9: 9967089085 | E9: VL4EC949 | F9: HBA1C / Total Cholesterol | G9: REPORTED | H9: 46216 | I9: =VLOOKUP(E9,Sheet2!A:C,3,0) -> PE00213700086079641 | J9: PE00213700086079641 | K9: https://www.thyrocare.com/DownloadReports/?token=31611dc4-5651-46eb-94ca-a46d00591145
A10: Uday Madhukar Likam | B10: 37 | C10: Male | D10: 9167795301 | E10: VL57DD7C | F10: HBA1C / Total Cholesterol | G10: REPORTED | H10: 46216 | I10: =VLOOKUP(E10,Sheet2!A:C,3,0) -> PE00213700086079192 | J10: PE00213700086079192 | K10: https://www.thyrocare.com/DownloadReports/?token=2f31fd60-e607-4183-9214-713e38b39b5c
A11: Prashant banarse | B11: 45 | C11: Male | D11: 7045052985 | E11: VL75E70B | F11: HBA1C / Total Cholesterol | G11: REPORTED | H11: 46216 | I11: =VLOOKUP(E11,Sheet2!A:C,3,0) -> PE00213700086079236 | J11: PE00213700086079236 | K11: https://www.thyrocare.com/DownloadReports/?token=b59c30af-71cb-436a-ae26-7ca78fd7792e
A12: Vinod Kolhe | B12: 47 | C12: Male | D12: 8976661355 | E12: VL2A91E9 | F12: HBA1C / Total Cholesterol | G12: REPORTED | H12: 46216 | I12: =VLOOKUP(E12,Sheet2!A:C,3,0) -> PE00213700086079363 | J12: PE00213700086079363 | K12: https://www.thyrocare.com/DownloadReports/?token=3755a3eb-3162-4b88-8910-98bea053fca8
A13: Reynold S Faroz | B13: 48 | C13: Male | D13: 9511780583 | E13: VL5FA431 | F13: HBA1C / Total Cholesterol | G13: REPORTED | H13: 46216 | I13: =VLOOKUP(E13,Sheet2!A:C,3,0) -> PE00213700086079868 | J13: PE00213700086079868 | K13: https://www.thyrocare.com/DownloadReports/?token=533c659c-fb20-4a41-811a-d8856efef8a3
... A117: Debasree Majumder | B117: 45 | C117: Female | D117: 9820218106 | E117: VL42FB42 | F117: HBA1C / Total Cholesterol | G117: REPORTED | H117: 46216 | I117: =VLOOKUP(E117,Sheet2!A:C,3,0) -> PE00213700086084716 | J117: PE00213700086084716 | K117: https://www.thyrocare.com/DownloadReports/?token=25246827-1b07-41cf-bf62-16d3b88ac091
A118: Savita Chhadi | B118: 24 | C118: Female | D118: 9021565294 | E118: VL8AC946 | F118: HBA1C / Total Cholesterol | G118: SERVICED | H118: 46216 | I118: =VLOOKUP(E118,Sheet2!A:C,3,0) -> #N/A
A119: Abhishek Mhatre | B119: 41 | C119: Male | D119: 8600318169 | E119: VL8DA75A | F119: HBA1C / Total Cholesterol | G119: REPORTED | H119: 46216 | I119: =VLOOKUP(E119,Sheet2!A:C,3,0) -> PE00213700086084057 | J119: PE00213700086084057 | K119: https://www.thyrocare.com/DownloadReports/?token=c7773b92-d123-4766-9733-b7c79b544645
A120: Shrikant | B120: 29 | C120: Male | D120: 9930728971 | E120: VLED10EC | F120: HBA1C / Total Cholesterol | G120: REPORTED | H120: 46216 | I120: =VLOOKUP(E120,Sheet2!A:C,3,0) -> PE00213700086085420 | J120: PE00213700086085420 | K120: https://www.thyrocare.com/DownloadReports/?token=c2e5efe7-2867-4e15-a8ed-d6a8049f999d
A121: Darshan Chikhalikar | B121: 48 | C121: Male | D121: 9833027207 | E121: VLC2BB95 | F121: HBA1C / Total Cholesterol | G121: REPORTED | H121: 46216 | I121: =VLOOKUP(E121,Sheet2!A:C,3,0) -> PE00213700086083945 | J121: PE00213700086083945 | K121: https://www.thyrocare.com/DownloadReports/?token=01d3bc92-5a1d-4f2b-be2f-4f474c4b3d8e
A122: Ajay Kurapati | B122: 27 | C122: Male | D122: 9767253499 | E122: VL967489 | F122: HBA1C / Total Cholesterol | G122: REPORTED | H122: 46216 | I122: =VLOOKUP(E122,Sheet2!A:C,3,0) -> PE00213700086085386 | J122: PE00213700086085386 | K122: https://www.thyrocare.com/DownloadReports/?token=d2ca3f2d-8b86-4d86-b573-e5b44827fa55
A123: Vitthal zaware | B123: 32 | C123: Male | D123: 9004917062 | E123: VL9EA302 | F123: HBA1C / Total Cholesterol | G123: REPORTED | H123: 46216 | I123: =VLOOKUP(E123,Sheet2!A:C,3,0) -> PE00213700086084190 | J123: PE00213700086084190 | K123: https://www.thyrocare.com/DownloadReports/?token=d70dede6-c115-47bd-beba-a36811b66959
A124: Shailesh Mayekar | B124: 35 | C124: Male | D124: 8692969739 | E124: VL21553A | F124: HBA1C / Total Cholesterol | G124: REPORTED | H124: 46216 | I124: =VLOOKUP(E124,Sheet2!A:C,3,0) -> PE00213700086084252 | J124: PE00213700086084252 | K124: https://www.thyrocare.com/DownloadReports/?token=88064c89-1a51-4fb4-a1fa-3f1b6b904afb
A125: Prasanna Patil | B125: 22 | C125: Male | D125: 9373417739 | E125: VL3C1BA6 | F125: HBA1C / Total Cholesterol | G125: REPORTED | H125: 46216 | I125: =VLOOKUP(E125,Sheet2!A:C,3,0) -> PE00213700086085368 | J125: PE00213700086085368 | K125: https://www.thyrocare.com/DownloadReports/?token=bfd90e00-2f84-4e9d-960c-4c1736a0f68b
A126: Avida Salian 50 | B126: 50 | C126: Female | D126: 9004845601 | E126: VL0C0769 | F126: HBA1C / Total Cholesterol | G126: REPORTED | H126: 46216 | I126: =VLOOKUP(E126,Sheet2!A:C,3,0) -> PE00213700086085350 | J126: PE00213700086085350 | K126: https://www.thyrocare.com/DownloadReports/?token=a8acfbec-85f1-44f7-a61d-2a92c549b57c
A127: Rushikesh Mhasu Wakchaure | B127: 27 | C127: Male | D127: 9975656847 | E127: VL5468F2 | F127: HBA1C / Total Cholesterol | G127: REPORTED | H127: 46216 | I127: =VLOOKUP(E127,Sheet2!A:C,3,0) -> PE00213700086084293 | J127: PE00213700086084293 | K127: https://www.thyrocare.com/DownloadReports/?token=27836f50-664e-4cc6-a2e8-6d4354356aa9
A128: Shreerang tukaram jadhav | B128: 39 | C128: Male | D128: 9819723043 | E128: VLD8C857 | F128: HBA1C / Total Cholesterol | G128: REPORTED | H128: 46216 | I128: =VLOOKUP(E128,Sheet2!A:C,3,0) -> PE00213700086085295 | J128: PE00213700086085295 | K128: https://www.thyrocare.com/DownloadReports/?token=b2c03cf3-bcd2-4c18-adc2-0f69f30d931a
A129: Raghuraj Vayeda | B129: 35 | C129: Male | D129: 9727799505 | E129: VLF638F1 | F129: HBA1C / Total Cholesterol | G129: REPORTED | H129: 46216 | I129: =VLOOKUP(E129,Sheet2!A:C,3,0) -> PE00213700086085270 | J129: PE00213700086085270 | K129: https://www.thyrocare.com/DownloadReports/?token=f738ad72-4428-4b8e-a458-852c759e6afb
A130: Vishal Suresh Waghmare | B130: 27 | C130: Male | D130: 8286550446 | E130: VLFA0899 | F130: HBA1C / Total Cholesterol | G130: REPORTED | H130: 46216 | I130: =VLOOKUP(E130,Sheet2!A:C,3,0) -> PE00213700086085242 | J130: PE00213700086085242 | K130: https://www.thyrocare.com/DownloadReports/?token=3732cf7b-02a0-4c57-abe2-28bee84565fb
... A182: Priti Parjane | B182: 26 | C182: Female | D182: 7820988893 | E182: VLA4A757 | F182: Thyroid Profile Test (T3, T4, UTSH) / TFT | G182: REPORTED | H182: 46216 | I182: =VLOOKUP(E182,Sheet2!A:C,3,0) -> AF28313700086083688 | J182: AF28313700086083688 | K182: https://www.thyrocare.com/DownloadReports/?token=d06d9e85-e0d0-4b2c-a487-2ae97656e4fc
A183: Shreya | B183: 33 | C183: Female | D183: 98924 53899 | E183: VLA45E42 | F183: HBA1C / Total Cholesterol | G183: REPORTED | H183: 46217 | I183: =VLOOKUP(E183,Sheet2!A:C,3,0) -> PE00214700086094415 | J183: PE00214700086094415 | K183: https://www.thyrocare.com/DownloadReports/?token=86dfe5c4-cc57-4421-bac1-ac72a867d6af
A184: Paresh Dharmaji Kubal | B184: 46 | C184: Male | D184: 9769466806 | E184: VL1899B1 | F184: HBA1C / Total Cholesterol | G184: REPORTED | H184: 46217 | I184: =VLOOKUP(E184,Sheet2!A:C,3,0) -> PE00214700086094479 | J184: PE00214700086094479 | K184: https://www.thyrocare.com/DownloadReports/?token=577ba7b2-2e7c-42ed-b5a5-5744dd807f92
A185: Pratish | B185: 45 | C185: Male | D185: 8425896488 | E185: VL91C637 | F185: HBA1C / Total Cholesterol | G185: REPORTED | H185: 46217 | I185: =VLOOKUP(E185,Sheet2!A:C,3,0) -> PE00214700086094467 | J185: PE00214700086094467 | K185: https://www.thyrocare.com/DownloadReports/?token=5262e95f-7705-4c11-9087-75469cb9de78
A186: Pradnesh H Raut | B186: 45 | C186: Male | D186: 9923775966 | E186: VLC9F409 | F186: HBA1C / Total Cholesterol | G186: REPORTED | H186: 46217 | I186: =VLOOKUP(E186,Sheet2!A:C,3,0) -> PE00214700086094560 | J186: PE00214700086094560 | K186: https://www.thyrocare.com/DownloadReports/?token=f67f69db-56cc-4ee6-a76a-f8c396b13e5b
A187: Amitkumar Khedekar | B187: 43 | C187: Male | D187: 9920339915 | E187: VL920443 | F187: HBA1C / Total Cholesterol | G187: REPORTED | H187: 46217 | I187: =VLOOKUP(E187,Sheet2!A:C,3,0) -> PE00214700086094612 | J187: PE00214700086094612 | K187: https://www.thyrocare.com/DownloadReports/?token=aa9ed158-6ddd-4372-b2ac-3e65dd5829bf
A188: Milind shinde | B188: 42 | C188: Male | D188: 7710015522 | E188: VLC33217 | F188: HBA1C / Total Cholesterol | G188: REPORTED | H188: 46217 | I188: =VLOOKUP(E188,Sheet2!A:C,3,0) -> PE00214700086094645 | J188: PE00214700086094645 | K188: https://www.thyrocare.com/DownloadReports/?token=2aad34e3-7e46-40cd-9c6e-7bc63e03e167
A189: Vinayak Dinkar Dhisal | B189: 42 | C189: Male | D189: 9619669261 | E189: VLA05390 | F189: HBA1C / Total Cholesterol | G189: REPORTED | H189: 46217 | I189: =VLOOKUP(E189,Sheet2!A:C,3,0) -> PE00214700086094779 | J189: PE00214700086094779 | K189: https://www.thyrocare.com/DownloadReports/?token=480a0b14-db43-4f10-bc84-55e57110f5cc
A190: Abhijit dighe | B190: 43 | C190: Male | D190: 9920767649 | E190: VL8DF7F6 | F190: HBA1C / Total Cholesterol | G190: REPORTED | H190: 46217 | I190: =VLOOKUP(E190,Sheet2!A:C,3,0) -> PE00214700086094822 | J190: PE00214700086094822 | K190: https://www.thyrocare.com/DownloadReports/?token=54be18fd-9b0f-44c4-ac6b-06cb965e0f41
A191: Parag | B191: 43 | C191: Male | D191: 9619775993 | E191: VLCCB579 | F191: HBA1C / Total Cholesterol | G191: REPORTED | H191: 46217 | I191: =VLOOKUP(E191,Sheet2!A:C,3,0) -> AF28314700086094524 | J191: AF28314700086094524 | K191: https://www.thyrocare.com/DownloadReports/?token=69faaae9-c237-45db-b3f8-adaf165728e2
A192: Dipti Pitre | B192: 39 | C192: Female | D192: 9819408644 | E192: VLC79C14 | F192: HBA1C / Total Cholesterol | G192: REPORTED | H192: 46217 | I192: =VLOOKUP(E192,Sheet2!A:C,3,0) -> PE00214700086094957 | J192: PE00214700086094957 | K192: https://www.thyrocare.com/DownloadReports/?token=a5556e71-35d3-42d3-b561-66ebc730cd14
A193: Nilesh Borkar | B193: 42 | C193: Male | D193: 9920955877 | E193: VLA8E14C | F193: HBA1C / Total Cholesterol | G193: REPORTED | H193: 46217 | I193: =VLOOKUP(E193,Sheet2!A:C,3,0) -> PE00214700086094702 | J193: PE00214700086094702 | K193: https://www.thyrocare.com/DownloadReports/?token=45f08359-68fb-465c-913c-71a3360975cd
A194: Trushnali Kelshikar | B194: 48 | C194: Female | D194: 9930779992 | E194: VLE5CCB8 | F194: HBA1C / Total Cholesterol | G194: REPORTED | H194: 46217 | I194: =VLOOKUP(E194,Sheet2!A:C,3,0) -> PE00214700086095007 | J194: PE00214700086095007 | K194: https://www.thyrocare.com/DownloadReports/?token=346692cf-ba45-4318-afd1-017ff13f5901
...

Sheet Sheet3
A1: ORDER_id | B1: id
A2: VLDC402D | B2: SP50529043 | C2: #N/A
A3: VL73AFE8 | B3: SP50650077 | C3: #N/A
A4: VL0291CC | B4: SP50715581 | C4: #N/A
A5: VL115222 | B5: SP50717992 | C5: #N/A
A6: VL34C654 | B6: SP50791091 | C6: #N/A
A7: VL81253F | B7: SP50795582 | C7: #N/A
A8: VL8BEBB4 | B8: SP50886836 | C8: HCL01C30111605940604
A9: VL32549A | B9: SP50909861 | C9: HCL29C16127273559140
A10: VL2B07A0 | B10: SP79785173 | C10: AH976161200079785173
A11: VL728397 | B11: SP86078475 | C11: PE00213700086078475
A12: VL99447E | B12: SP86078627 | C12: PE00213700086078627
A13: VL006C63 | B13: SP86078694 | C13: PE00213700086078694
A14: VLEBFCE1 | B14: SP86078872 | C14: PE00213700086078872
A15: VL9E0BA1 | B15: SP86078901 | C15: PE00213700086078901
A16: VL4C0DBA | B16: SP86078931 | C16: PE00213700086078931
A17: VL26F7E5 | B17: SP86078961 | C17: PE00213700086078961
A18: VL7A98D8 | B18: SP86079018 | C18: PE00213700086079018
A19: VL4F389B | B19: SP86079091 | C19: PE00213700086079091
... A166: VL89835D | B166: SP86085429 | C166: PE00213700086085429
A167: VL8AC946 | B167: SP86085437 | C167: #N/A
A168: VL7D0F6A | B168: SP86085453 | C168: PE00213700086085453
A169: VLCF8CF2 | B169: SP86085462 | C169: PE00213700086085462
A170: VL88BAC9 | B170: SP86085490 | C170: PE00213700086085490
A171: VLC83A1D | B171: SP86085534 | C171: AF28313700086085534
A172: VL3EC6FE | B172: SP86085676 | C172: PE00213700086085676
A173: VL44ABFC | B173: SP86085707 | C173: PE00213700086085707
A174: VL6825C0 | B174: SP86085752 | C174: PE00214700086085752
A175: VL959374 | B175: SP86085765 | C175: PE00213700086085765
A176: VL7BEF39 | B176: SP86085781 | C176: PE00213700086085781
A177: VLCDCA79 | B177: SP86085835 | C177: PE00213700086085835
A178: VLFF74DF | B178: SP86085851 | C178: PE00213700086085851
A179: VL0E1A12 | B179: SP86085865 | C179: PE00213700086085865
... A1283: VL8DFE50 | B1283: SPAP35343333 | C1283: AF2831670AP35343333

Sheet Sheet2
A1: VLDC402D | B1: SP50529043 | C1: #N/A
A2: VL81253F | B2: SP50795582 | C2: #N/A
A3: VL8BEBB4 | B3: SP50886836 | C3: HCL01C30111605940604
A4: VL32549A | B4: SP50909861 | C4: HCL29C16127273559140
A5: VL006C63 | B5: SP86078694 | C5: PE00213700086078694
A6: VL9E0BA1 | B6: SP86078901 | C6: PE00213700086078901
A7: VL4C0DBA | B7: SP86078931 | C7: PE00213700086078931
A8: VL26F7E5 | B8: SP86078961 | C8: PE00213700086078961
A9: VL581C89 | B9: SP86079764 | C9: PE00213700086079764
A10: VL979246 | B10: SP86079792 | C10: PE00213700086079792
A11: VLE914E2 | B11: SP86079814 | C11: PE00213700086079814
A12: VLF7FEF8 | B12: SP86079849 | C12: PE00213700086079849
A13: VLD8ABB8 | B13: SP86080162 | C13: PE00213700086080162
A14: VL22B0BE | B14: SP86080224 | C14: PE00213700086080224
... A332: VL8DFE50 | B332: SPAP35343333 | C332: AF2831670AP35343333
A333: VLDC402D | B333: SP50529043 | C333: #N/A
A334: VL73AFE8 | B334: SP50650077 | C334: #N/A
A335: VL0291CC | B335: SP50715581 | C335: #N/A
A336: VL115222 | B336: SP50717992 | C336: #N/A
A337: VL34C654 | B337: SP50791091 | C337: #N/A
A338: VL81253F | B338: SP50795582 | C338: #N/A
A339: VL8BEBB4 | B339: SP50886836 | C339: HCL01C30111605940604
A340: VL32549A | B340: SP50909861 | C340: HCL29C16127273559140
A341: VL2B07A0 | B341: SP79785173 | C341: AH976161200079785173
A342: VL728397 | B342: SP86078475 | C342: PE00213700086078475
A343: VL99447E | B343: SP86078627 | C343: PE00213700086078627
A344: VL006C63 | B344: SP86078694 | C344: PE00213700086078694
A345: VLEBFCE1 | B345: SP86078872 | C345: PE00213700086078872
A346: VL9E0BA1 | B346: SP86078901 | C346: PE00213700086078901
A347: VL4C0DBA | B347: SP86078931 | C347: PE00213700086078931
A348: VL26F7E5 | B348: SP86078961 | C348: PE00213700086078961
A349: VL7A98D8 | B349: SP86079018 | C349: PE00213700086079018
A350: VL4F389B | B350: SP86079091 | C350: PE00213700086079091
... A497: VL89835D | B497: SP86085429 | C497: PE00213700086085429
A498: VL8AC946 | B498: SP86085437 | C498: #N/A
A499: VL7D0F6A | B499: SP86085453 | C499: PE00213700086085453
A500: VLCF8CF2 | B500: SP86085462 | C500: PE00213700086085462
A501: VL88BAC9 | B501: SP86085490 | C501: PE00213700086085490
A502: VLC83A1D | B502: SP86085534 | C502: AF28313700086085534
A503: VL3EC6FE | B503: SP86085676 | C503: PE00213700086085676
...
